{
 "cells": [
  {
   "cell_type": "code",
   "execution_count": 4,
   "id": "ded364e5",
   "metadata": {},
   "outputs": [],
   "source": [
    "from tensorflow.keras.optimizers import RMSprop\n",
    "from tensorflow.keras.preprocessing.image import ImageDataGenerator\n",
    "import cv2\n",
    "from tensorflow.keras.models import Sequential\n",
    "from tensorflow.keras.layers import Conv2D, Input, ZeroPadding2D, BatchNormalization, Activation, MaxPooling2D, Flatten, Dense,Dropout\n",
    "from tensorflow.keras.models import Model, load_model\n",
    "from keras.callbacks import TensorBoard, ModelCheckpoint\n",
    "from sklearn.model_selection import train_test_split\n",
    "from sklearn.metrics import f1_score\n",
    "from sklearn.utils import shuffle\n",
    "import imutils\n",
    "import numpy as np"
   ]
  },
  {
   "cell_type": "raw",
   "id": "8adeb072",
   "metadata": {},
   "source": []
  },
  {
   "cell_type": "code",
   "execution_count": 3,
   "id": "749253d2",
   "metadata": {
    "scrolled": true
   },
   "outputs": [
    {
     "name": "stdout",
     "output_type": "stream",
     "text": [
      "Collecting imutils\n",
      "  Using cached imutils-0.5.4.tar.gz (17 kB)\n",
      "Building wheels for collected packages: imutils\n",
      "  Building wheel for imutils (setup.py): started\n",
      "  Building wheel for imutils (setup.py): finished with status 'done'\n",
      "  Created wheel for imutils: filename=imutils-0.5.4-py3-none-any.whl size=25860 sha256=ced633bd2d58a223c127931d7332ae99e6ed3f9ac30d00d2b8a294d09885e967\n",
      "  Stored in directory: c:\\users\\gurumurthythonukunoo\\appdata\\local\\pip\\cache\\wheels\\59\\1b\\52\\0dea905f8278d5514dc4d0be5e251967f8681670cadd3dca89\n",
      "Successfully built imutils\n",
      "Installing collected packages: imutils\n",
      "Successfully installed imutils-0.5.4\n"
     ]
    }
   ],
   "source": [
    "!pip install imutils"
   ]
  },
  {
   "cell_type": "code",
   "execution_count": 5,
   "id": "867aad4e",
   "metadata": {},
   "outputs": [],
   "source": [
    "model = Sequential([\n",
    "    Conv2D(100, (3,3), activation='relu', input_shape=(150, 150, 3)),\n",
    "    MaxPooling2D(2,2),\n",
    "    \n",
    "    Conv2D(100, (3,3), activation='relu'),\n",
    "    MaxPooling2D(2,2),\n",
    "    \n",
    "    Flatten(),\n",
    "    Dropout(0.5),\n",
    "    Dense(50, activation='relu'),\n",
    "    Dense(2, activation='softmax')\n",
    "])\n",
    "model.compile(optimizer='adam', loss='binary_crossentropy', metrics=['acc'])"
   ]
  },
  {
   "cell_type": "code",
   "execution_count": 7,
   "id": "877cd4bc",
   "metadata": {},
   "outputs": [
    {
     "name": "stdout",
     "output_type": "stream",
     "text": [
      "Found 1315 images belonging to 2 classes.\n",
      "Found 194 images belonging to 2 classes.\n"
     ]
    }
   ],
   "source": [
    "TRAINING_DIR = \"Dataset/train\"\n",
    "train_datagen = ImageDataGenerator(rescale=1.0/255,\n",
    "                                   rotation_range=40,\n",
    "                                   width_shift_range=0.2,\n",
    "                                   height_shift_range=0.2,\n",
    "                                   shear_range=0.2,\n",
    "                                   zoom_range=0.2,\n",
    "                                   horizontal_flip=True,\n",
    "                                   fill_mode='nearest')\n",
    "train_generator = train_datagen.flow_from_directory(TRAINING_DIR, \n",
    "                                                    batch_size=10, \n",
    "                                                    target_size=(150, 150))\n",
    "VALIDATION_DIR = \"Dataset/test\"\n",
    "validation_datagen = ImageDataGenerator(rescale=1.0/255)\n",
    "validation_generator = validation_datagen.flow_from_directory(VALIDATION_DIR, \n",
    "                                                         batch_size=10, \n",
    "                                                         target_size=(150, 150))"
   ]
  },
  {
   "cell_type": "code",
   "execution_count": 8,
   "id": "857e004a",
   "metadata": {},
   "outputs": [],
   "source": [
    "checkpoint = ModelCheckpoint('model2-{epoch:03d}.model',monitor='val_loss',verbose=0,save_best_only=True,mode='auto')"
   ]
  },
  {
   "cell_type": "code",
   "execution_count": 10,
   "id": "b2d2f1f7",
   "metadata": {},
   "outputs": [
    {
     "name": "stderr",
     "output_type": "stream",
     "text": [
      "<ipython-input-10-6272b23e5a0b>:1: UserWarning: `Model.fit_generator` is deprecated and will be removed in a future version. Please use `Model.fit`, which supports generators.\n",
      "  history = model.fit_generator(train_generator,\n"
     ]
    },
    {
     "name": "stdout",
     "output_type": "stream",
     "text": [
      "Epoch 1/10\n",
      " 26/132 [====>.........................] - ETA: 51s - loss: 0.6935 - acc: 0.4769"
     ]
    },
    {
     "ename": "UnknownError",
     "evalue": " UnidentifiedImageError: cannot identify image file <_io.BytesIO object at 0x00000232062A5900>\nTraceback (most recent call last):\n\n  File \"C:\\Vishnu Conda\\lib\\site-packages\\tensorflow\\python\\ops\\script_ops.py\", line 275, in __call__\n    ret = func(*args)\n\n  File \"C:\\Vishnu Conda\\lib\\site-packages\\tensorflow\\python\\autograph\\impl\\api.py\", line 649, in wrapper\n    return func(*args, **kwargs)\n\n  File \"C:\\Vishnu Conda\\lib\\site-packages\\tensorflow\\python\\data\\ops\\dataset_ops.py\", line 992, in generator_py_func\n    values = next(generator_state.get_iterator(iterator_id))\n\n  File \"C:\\Vishnu Conda\\lib\\site-packages\\keras\\engine\\data_adapter.py\", line 834, in wrapped_generator\n    for data in generator_fn():\n\n  File \"C:\\Vishnu Conda\\lib\\site-packages\\keras\\engine\\data_adapter.py\", line 960, in generator_fn\n    yield x[i]\n\n  File \"C:\\Vishnu Conda\\lib\\site-packages\\keras_preprocessing\\image\\iterator.py\", line 65, in __getitem__\n    return self._get_batches_of_transformed_samples(index_array)\n\n  File \"C:\\Vishnu Conda\\lib\\site-packages\\keras_preprocessing\\image\\iterator.py\", line 227, in _get_batches_of_transformed_samples\n    img = load_img(filepaths[j],\n\n  File \"C:\\Vishnu Conda\\lib\\site-packages\\keras_preprocessing\\image\\utils.py\", line 114, in load_img\n    img = pil_image.open(io.BytesIO(f.read()))\n\n  File \"C:\\Vishnu Conda\\lib\\site-packages\\PIL\\Image.py\", line 2967, in open\n    raise UnidentifiedImageError(\n\nPIL.UnidentifiedImageError: cannot identify image file <_io.BytesIO object at 0x00000232062A5900>\n\n\n\t [[{{node PyFunc}}]]\n\t [[IteratorGetNext]] [Op:__inference_train_function_902]",
     "output_type": "error",
     "traceback": [
      "\u001b[1;31m---------------------------------------------------------------------------\u001b[0m",
      "\u001b[1;31mUnknownError\u001b[0m                              Traceback (most recent call last)",
      "\u001b[1;32m<ipython-input-10-6272b23e5a0b>\u001b[0m in \u001b[0;36m<module>\u001b[1;34m\u001b[0m\n\u001b[1;32m----> 1\u001b[1;33m history = model.fit_generator(train_generator,\n\u001b[0m\u001b[0;32m      2\u001b[0m                               \u001b[0mepochs\u001b[0m\u001b[1;33m=\u001b[0m\u001b[1;36m10\u001b[0m\u001b[1;33m,\u001b[0m\u001b[1;33m\u001b[0m\u001b[1;33m\u001b[0m\u001b[0m\n\u001b[0;32m      3\u001b[0m                               \u001b[0mvalidation_data\u001b[0m\u001b[1;33m=\u001b[0m\u001b[0mvalidation_generator\u001b[0m\u001b[1;33m,\u001b[0m\u001b[1;33m\u001b[0m\u001b[1;33m\u001b[0m\u001b[0m\n\u001b[0;32m      4\u001b[0m                               callbacks=[checkpoint])\n",
      "\u001b[1;32mC:\\Vishnu Conda\\lib\\site-packages\\keras\\engine\\training.py\u001b[0m in \u001b[0;36mfit_generator\u001b[1;34m(self, generator, steps_per_epoch, epochs, verbose, callbacks, validation_data, validation_steps, validation_freq, class_weight, max_queue_size, workers, use_multiprocessing, shuffle, initial_epoch)\u001b[0m\n\u001b[0;32m   2014\u001b[0m         \u001b[1;34m'Please use `Model.fit`, which supports generators.'\u001b[0m\u001b[1;33m,\u001b[0m\u001b[1;33m\u001b[0m\u001b[1;33m\u001b[0m\u001b[0m\n\u001b[0;32m   2015\u001b[0m         stacklevel=2)\n\u001b[1;32m-> 2016\u001b[1;33m     return self.fit(\n\u001b[0m\u001b[0;32m   2017\u001b[0m         \u001b[0mgenerator\u001b[0m\u001b[1;33m,\u001b[0m\u001b[1;33m\u001b[0m\u001b[1;33m\u001b[0m\u001b[0m\n\u001b[0;32m   2018\u001b[0m         \u001b[0msteps_per_epoch\u001b[0m\u001b[1;33m=\u001b[0m\u001b[0msteps_per_epoch\u001b[0m\u001b[1;33m,\u001b[0m\u001b[1;33m\u001b[0m\u001b[1;33m\u001b[0m\u001b[0m\n",
      "\u001b[1;32mC:\\Vishnu Conda\\lib\\site-packages\\keras\\utils\\traceback_utils.py\u001b[0m in \u001b[0;36merror_handler\u001b[1;34m(*args, **kwargs)\u001b[0m\n\u001b[0;32m     65\u001b[0m     \u001b[1;32mexcept\u001b[0m \u001b[0mException\u001b[0m \u001b[1;32mas\u001b[0m \u001b[0me\u001b[0m\u001b[1;33m:\u001b[0m  \u001b[1;31m# pylint: disable=broad-except\u001b[0m\u001b[1;33m\u001b[0m\u001b[1;33m\u001b[0m\u001b[0m\n\u001b[0;32m     66\u001b[0m       \u001b[0mfiltered_tb\u001b[0m \u001b[1;33m=\u001b[0m \u001b[0m_process_traceback_frames\u001b[0m\u001b[1;33m(\u001b[0m\u001b[0me\u001b[0m\u001b[1;33m.\u001b[0m\u001b[0m__traceback__\u001b[0m\u001b[1;33m)\u001b[0m\u001b[1;33m\u001b[0m\u001b[1;33m\u001b[0m\u001b[0m\n\u001b[1;32m---> 67\u001b[1;33m       \u001b[1;32mraise\u001b[0m \u001b[0me\u001b[0m\u001b[1;33m.\u001b[0m\u001b[0mwith_traceback\u001b[0m\u001b[1;33m(\u001b[0m\u001b[0mfiltered_tb\u001b[0m\u001b[1;33m)\u001b[0m \u001b[1;32mfrom\u001b[0m \u001b[1;32mNone\u001b[0m\u001b[1;33m\u001b[0m\u001b[1;33m\u001b[0m\u001b[0m\n\u001b[0m\u001b[0;32m     68\u001b[0m     \u001b[1;32mfinally\u001b[0m\u001b[1;33m:\u001b[0m\u001b[1;33m\u001b[0m\u001b[1;33m\u001b[0m\u001b[0m\n\u001b[0;32m     69\u001b[0m       \u001b[1;32mdel\u001b[0m \u001b[0mfiltered_tb\u001b[0m\u001b[1;33m\u001b[0m\u001b[1;33m\u001b[0m\u001b[0m\n",
      "\u001b[1;32mC:\\Vishnu Conda\\lib\\site-packages\\tensorflow\\python\\eager\\execute.py\u001b[0m in \u001b[0;36mquick_execute\u001b[1;34m(op_name, num_outputs, inputs, attrs, ctx, name)\u001b[0m\n\u001b[0;32m     56\u001b[0m   \u001b[1;32mtry\u001b[0m\u001b[1;33m:\u001b[0m\u001b[1;33m\u001b[0m\u001b[1;33m\u001b[0m\u001b[0m\n\u001b[0;32m     57\u001b[0m     \u001b[0mctx\u001b[0m\u001b[1;33m.\u001b[0m\u001b[0mensure_initialized\u001b[0m\u001b[1;33m(\u001b[0m\u001b[1;33m)\u001b[0m\u001b[1;33m\u001b[0m\u001b[1;33m\u001b[0m\u001b[0m\n\u001b[1;32m---> 58\u001b[1;33m     tensors = pywrap_tfe.TFE_Py_Execute(ctx._handle, device_name, op_name,\n\u001b[0m\u001b[0;32m     59\u001b[0m                                         inputs, attrs, num_outputs)\n\u001b[0;32m     60\u001b[0m   \u001b[1;32mexcept\u001b[0m \u001b[0mcore\u001b[0m\u001b[1;33m.\u001b[0m\u001b[0m_NotOkStatusException\u001b[0m \u001b[1;32mas\u001b[0m \u001b[0me\u001b[0m\u001b[1;33m:\u001b[0m\u001b[1;33m\u001b[0m\u001b[1;33m\u001b[0m\u001b[0m\n",
      "\u001b[1;31mUnknownError\u001b[0m:  UnidentifiedImageError: cannot identify image file <_io.BytesIO object at 0x00000232062A5900>\nTraceback (most recent call last):\n\n  File \"C:\\Vishnu Conda\\lib\\site-packages\\tensorflow\\python\\ops\\script_ops.py\", line 275, in __call__\n    ret = func(*args)\n\n  File \"C:\\Vishnu Conda\\lib\\site-packages\\tensorflow\\python\\autograph\\impl\\api.py\", line 649, in wrapper\n    return func(*args, **kwargs)\n\n  File \"C:\\Vishnu Conda\\lib\\site-packages\\tensorflow\\python\\data\\ops\\dataset_ops.py\", line 992, in generator_py_func\n    values = next(generator_state.get_iterator(iterator_id))\n\n  File \"C:\\Vishnu Conda\\lib\\site-packages\\keras\\engine\\data_adapter.py\", line 834, in wrapped_generator\n    for data in generator_fn():\n\n  File \"C:\\Vishnu Conda\\lib\\site-packages\\keras\\engine\\data_adapter.py\", line 960, in generator_fn\n    yield x[i]\n\n  File \"C:\\Vishnu Conda\\lib\\site-packages\\keras_preprocessing\\image\\iterator.py\", line 65, in __getitem__\n    return self._get_batches_of_transformed_samples(index_array)\n\n  File \"C:\\Vishnu Conda\\lib\\site-packages\\keras_preprocessing\\image\\iterator.py\", line 227, in _get_batches_of_transformed_samples\n    img = load_img(filepaths[j],\n\n  File \"C:\\Vishnu Conda\\lib\\site-packages\\keras_preprocessing\\image\\utils.py\", line 114, in load_img\n    img = pil_image.open(io.BytesIO(f.read()))\n\n  File \"C:\\Vishnu Conda\\lib\\site-packages\\PIL\\Image.py\", line 2967, in open\n    raise UnidentifiedImageError(\n\nPIL.UnidentifiedImageError: cannot identify image file <_io.BytesIO object at 0x00000232062A5900>\n\n\n\t [[{{node PyFunc}}]]\n\t [[IteratorGetNext]] [Op:__inference_train_function_902]"
     ]
    }
   ],
   "source": [
    "history = model.fit_generator(train_generator,\n",
    "                              epochs=10,\n",
    "                              validation_data=validation_generator,\n",
    "                              callbacks=[checkpoint])\n"
   ]
  },
  {
   "cell_type": "code",
   "execution_count": 14,
   "id": "c2b43ebf",
   "metadata": {},
   "outputs": [],
   "source": [
    "import os.path\n",
    "\n",
    "if os.path.isfile('models/model_mask.h5') is False:\n",
    "    model.save('models/model_mask.h5')"
   ]
  }
 ],
 "metadata": {
  "kernelspec": {
   "display_name": "Python 3",
   "language": "python",
   "name": "python3"
  },
  "language_info": {
   "codemirror_mode": {
    "name": "ipython",
    "version": 3
   },
   "file_extension": ".py",
   "mimetype": "text/x-python",
   "name": "python",
   "nbconvert_exporter": "python",
   "pygments_lexer": "ipython3",
   "version": "3.8.8"
  }
 },
 "nbformat": 4,
 "nbformat_minor": 5
}
